<?xml version="1.0" ?>
<!-- =================================================================================== -->
<!-- |    This document was autogenerated by xacro from arm.urdf.xacro                 | -->
<!-- |    EDITING THIS FILE BY HAND IS NOT RECOMMENDED                                 | -->
<!-- =================================================================================== -->
<robot name="two_link_arm">
  <!-- <xacro:property name="props" value="${load_yaml('$(find simple_arm)/config/arm.yaml')}" />

<xacro:property name="l1" value="${props['L1']}" />
<xacro:property name="l2" value="${props['L2']}" /> -->
  <link name="base">
    <visual>
      <geometry>
        <sphere radius="0.1"/>
      </geometry>
      <material name="green_mat">
        <color rgba="0 1 0 1"/>
      </material>
    </visual>
  </link>
  <link name="L1">
    <visual>
      <origin rpy="1.5707963267948966 0 -1.5707963267948966" xyz="1.0 0 0"/>
      <geometry>
        <cylinder length="2.0" radius="0.1"/>
      </geometry>
      <material name="green_mat">
        <color rgba="0 1 0 1"/>
      </material>
    </visual>
  </link>
  <link name="L2">
    <visual>
      <origin rpy="1.5707963267948966 0 -1.5707963267948966" xyz="0.5 0 0"/>
      <geometry>
        <cylinder length="1.0" radius="0.1"/>
      </geometry>
      <material name="red_mat">
        <color rgba="1 0 0 1"/>
      </material>
    </visual>
  </link>
  <link name="End_Effector">
    <visual>
      <origin rpy="0 0 0" xyz="0 0 0"/>
      <geometry>
        <sphere radius="0.1"/>
      </geometry>
      <material name="green_mat">
        <color rgba="0 1 0 0"/>
      </material>
    </visual>
  </link>
  <joint name="joint1" type="continuous">
    <axis xyz="0 0 1"/>
    <parent link="base"/>
    <child link="L1"/>
  </joint>
  <joint name="joint2" type="continuous">
    <origin rpy="0 0 0" xyz="2.0 0 0"/>
    <axis xyz="0 0 1"/>
    <parent link="L1"/>
    <child link="L2"/>
  </joint>
  <joint name="end" type="continuous">
    <origin rpy="0 0 0" xyz="1.0 0 0"/>
    <parent link="L2"/>
    <child link="End_Effector"/>
  </joint>
</robot>
